Workbook

Sheet 1. Cover & Summary
B1: IS 11384:2022 CCD Example 001
B3: CONCRETE-ENCASED RECTANGULAR COMPOSITE COLUMN
B5: EXAMPLE DESCRIPTION
B6: =CONCATENATE("Compression, moment, and shear capacities and demand/capacity ratio are calculated for concrete-encased rectangular section member at mid-height as shown below. It is simply supported with a length of ",FIXED('2. Properties'!D24/1000,1,TRUE)," meters.") -> Compression, moment, and shear capacities and demand/capacity ratio are calculated for concrete-encased rectangular section member at mid-height as shown below. It is simply supported with a length of 7.0 meters.
B10: GEOMETRY, PROPERTIES AND LOADING
I11: Overall width of column (along Z axis) | J11: = | K11: ='2. Properties'!D34 -> 400 | L11: mm
I12: Overall depth of column (along Y axis) | J12: = | K12: ='2. Properties'!D35 -> 400 | L12: mm
I13: Depth of I section (along Z axis) | J13: = | K13: ='2. Properties'!D37 -> 256 | L13: mm
I14: Width of I section (along Y axis) | J14: = | K14: ='2. Properties'!D36 -> 260 | L14: mm
I15: Effective cover of reinforcement | J15: = | K15: =(K12-'2. Properties'!D42*2)/2 -> 41 | L15: mm
I16: Length of column | J16: = | K16: ='2. Properties'!D24/1000 -> 7 | L16: mm
H18: center to center distance between reinforcemt :
H19: Along Z axis | J19: = | K19: =(K11-K15*2)/2 -> 159 | L19: mm
H20: Along Y axis | J20: = | K20: =(K12-K15*2)/2 -> 159 | L20: mm
H22: Distance of I section from face of column :
H23: Along Z axis | J23: = | K23: =(K11-K13)/2 -> 72 | L23: mm
H24: Along Y axis | J24: = | K24: =(K12-K14)/2 -> 70 | L24: mm
B27: (The dimensions of the cross-section are in mm.)
B28: ="Dead: P = "&TEXT('2. Properties'!$D$28,"#,##0")&" kN" -> Dead: P = 1,200 kN | K28: =LOWER(B3) -> concrete-encased rectangular composite column
B29: ="Live: P = " &TEXT('2. Properties'!$D$29,"#,##0")&" kN, My = "&TEXT('2. Properties'!$D$30,"#,##0")&" kN - m, Mz = "&TEXT('2. Properties'!$D$31,"#,##0")&" kN - m " -> Live: P = 600 kN, My = 380 kN - m, Mz = 50 kN - m
B31: TECHNICAL FEATURES TESTED
B33: ➤ Axial compressive strength
B34: ➤ Major moment strength
B35: ➤ Shear strength
B36: ➤ Demand/Capacity ratio.
B38: Applicable Programs | C38: ➤ ETABS | H38: RESULTS COMPARISON
B40: Summary of results :
B42: Output Parameter | C42: Independent results | H42: COMPUTER FILE: IS 11384 2022 CCD Ex001
B43: Axial - Pd (kN) | C43: =ROUND('4. z-Buckling'!$E$18,0) -> 5701
B44: Axial - P'd,C,z (kN) | C44: =ROUND('4. z-Buckling'!$E$43,0) -> 1835
B45: Axial - P'd,C,y (kN) | C45: =ROUND('4. z-Buckling'!$E$88,0) -> 3884
B46: Axial reduction factor - χz | C46: =ROUND('5. Global+2nd'!$D$8,2) -> 0.76
B47: Axial reduction factor - χy | C47: =ROUND('5. Global+2nd'!$D$16,2) -> 0.62
B48: Flexure – Mmax,z (kN-m) | C48: =ROUND('4. z-Buckling'!$E$48,0) -> 505
B49: Flexure – Mdz (kN-m) | C49: =ROUND('4. z-Buckling'!$E$46,0) -> 468
B50: Flexure – Mmax,y (kN-m) | C50: =ROUND('4. z-Buckling'!$E$92,0) -> 310
B51: Flexure – Mdy (kN-m) | C51: =ROUND('4. z-Buckling'!$E$90,0) -> 187
B52: Shear - Vdy (kN) | C52: =ROUND('6. Shear+DC'!$D$7,0) -> 544
B53: Shear - Vdz (kN) | C53: =ROUND('6. Shear+DC'!$D$15,0) -> 1764
B54: D/C – Combined Axial and Biaxial Bending | C54: =ROUND('6. Shear+DC'!$D$48,3) -> 1.381 | H54: The results show excellent match with independent results.
...

Sheet 2. Properties
B1: Properties:
C2: Material:
D3: Steel: Fe345
B4: Es = | D4: 210000 | E4: N/mm2
B5: fy = | D5: 345 | E5: N/mm2
B6: γm0 = | D6: 1.1
D8: Concrete: M30
B9: Ecm = | D9: 27386 | E9: N/mm2
B10: fck = | D10: 30 | E10: N/mm2
B11: γc = | D11: 1.5 | Q11: Overall width of column (along Z axis) | R11: = | S11: ='2. Properties'!D34 -> 400 | T11: mm
B12: αc = | D12: 0.85 | Q12: Overall depth of column (along Y axis) | R12: = | S12: ='2. Properties'!D35 -> 400 | T12: mm
B13: αcc = | D13: 1 | Q13: Depth of I section (along Z axis) | R13: = | S13: ='2. Properties'!D37 -> 256 | T13: mm
B14: η = | D14: 1 | Q14: Width of I section (along Y axis) | R14: = | S14: ='2. Properties'!D36 -> 260 | T14: mm
Q15: Effective cover of reinforcement | R15: = | S15: =(S12-D42*2)/2 -> 41 | T15: mm
D16: Reinforcement: HYSD415 | Q16: Length of column | R16: = | S16: ='2. Properties'!D24/1000 -> 7 | T16: mm
B17: Est = | D17: 200000 | E17: N/mm2
B18: fyk = | D18: 415 | E18: N/mm2 | P18: center to center distance between reinforcemt :
B19: γk = | D19: 1.15 | P19: Along Z axis | R19: = | S19: =(S11-S15*2)/2 -> 159 | T19: mm
P20: Along Y axis | R20: = | S20: =(S12-S15*2)/2 -> 159 | T20: mm
C21: Member:
B22: Ky = | D22: 1 | F22: pinned-pinned condition | P22: Distance of I section from face of column :
B23: Kz = | D23: 1 | F23: pinned-pinned condition | P23: Along Z axis | R23: = | S23: =(S11-S13)/2 -> 72 | T23: mm
B24: Ly = | D24: 7000 | E24: mm | P24: Along Y axis | R24: = | S24: =(S12-S14)/2 -> 70 | T24: mm
B25: Lz = | D25: 7000 | E25: mm
C27: Loadings: | I27: Utilization ratios :
B28: PD = | D28: 1200 | E28: kN | F28: Dead ;
B29: PL = | D29: 600 | E29: kN | F29: Live ; | I29: Global buckling under axial load: | M29: Shear design:
B30: My = | D30: 380 | E30: kN-m | F30: Live Bending Moment about y Axis ; | I30: P/(χz Pd) | J30: = | K30: ='5. Global+2nd'!D9 -> 0.41484018 | M30: Vy/Vd,y | N30: = | O30: ='6. Shear+DC'!D8 -> 0.099830775
B31: Mz = | D31: 50 | E31: kN-m | F31: Live Bending Moment about z Axis | I31: P/(χy Pd) | J31: = | K31: ='5. Global+2nd'!D17 -> 0.51040072 | M31: Vz/Vd,z | N31: = | O31: ='6. Shear+DC'!D16 -> 0.0040485307
C33: Cross-section dimensions (from figure, dimensions in mm): | I33: Demand/Capacity (D/C) ratio:
B34: bc = | D34: 400 | E34: mm | F34: concrete width (y-direction) | I34: Pc,y/Pd,y | J34: = | K34: ='6. Shear+DC'!D27 -> 0.45250123
B35: hc = | D35: 400 | E35: mm | F35: concrete depth (z-direction) | I35: Pc,z/Pd,z | J35: = | K35: ='6. Shear+DC'!D29 -> 0.38464347
B36: h = | D36: 260 | E36: mm | F36: steel I overall depth | I36: P/Pd,y | J36: = | K36: ='6. Shear+DC'!D31 -> 0.3157452
B37: bf = | D37: 256 | E37: mm | F37: steel I flange width | I37: P/Pd,z | J37: = | K37: ='6. Shear+DC'!D33 -> 0.3157452
B38: tf = | D38: 17.3 | E38: mm | F38: steel I flange thickness | I38: →μdd (y-axis) | J38: = | K38: ='6. Shear+DC'!D38 -> 0.644464
B39: tw = | D39: 10.5 | E39: mm | F39: steel I web thickness | I39: →μdd (z-axis) | J39: = | K39: ='6. Shear+DC'!D43 -> 0.83896332
B40: db = | D40: 12 | E40: mm | F40: =CONCATENATE(D40," dia bar (",D41," corner bars, per figure)") -> 12 dia bar (4 corner bars, per figure) | I40: My/(μdd Mdd) | J40: = | K40: ='6. Shear+DC'!D45 -> 0.414134
B41: n = | D41: 4 | E41: Nos. | F41: number of bars | I41: Mz/(μdd Mdd) | J41: = | K41: ='6. Shear+DC'!D46 -> 0.96702826
B42: e = | D42: 159 | E42: mm | F42: bar eccentricity from centroid in both axes (per figure) | I42: My/(μdd Mdd) + Mz/(μdd Mdd) | J42: = | K42: ='6. Shear+DC'!D48 -> 1.3811623

Sheet 3. Sect Props
C1: Required strengths: for the section in the middle
B3: P = | C3: PD + PL
C4: =CONCATENATE("= ",'2. Properties'!$D$28," + ",'2. Properties'!$D$29) -> = 1200 + 600 | D4: ='2. Properties'!$D$28+'2. Properties'!$D$29 -> 1800 | E4: kN
B5: Mz = | C5: =CONCATENATE(" ",'2. Properties'!$D$30," / 2") -> 380 / 2 | D5: ='2. Properties'!$D$30/2 -> 190 | E5: kN
B6: My = | C6: =CONCATENATE(" ",'2. Properties'!$D$31," / 2") -> 50 / 2 | D6: ='2. Properties'!$D$31/2 -> 25 | E6: kN
B7: Vy = | C7: My/Ly
C8: =CONCATENATE("= ",'2. Properties'!$D$30," / ",FIXED('2. Properties'!D24/1000,1,TRUE)) -> = 380 / 7.0 | D8: ='2. Properties'!$D$30/('2. Properties'!D24/1000) -> 54.285714 | E8: kN
B9: Vz = | C9: Mz/Lz
C10: =CONCATENATE("= ",'2. Properties'!$D$31," / ",FIXED('2. Properties'!D24/1000,1,TRUE)) -> = 50 / 7.0 | D10: ='2. Properties'!$D$31/('2. Properties'!D25/1000) -> 7.1428571 | E10: kN
C12: Section properties:
C14: Embedded steel I-section:
B15: As = | C15: 2 bf tf + (h − 2 tf) tw
C16: =CONCATENATE("= 2 x ",FIXED('2. Properties'!$D$37,0,TRUE)," x ",FIXED('2. Properties'!$D$38,0,TRUE)," + (",FIXED('2. Properties'!$D$36,0,TRUE)," - 2 x ",FIXED('2. Properties'!$D$38,0,TRUE),") x ",FIXED('2. Properties'!$D$39,0,TRUE)) -> = 2 x 256 x 17 + (260 - 2 x 17) x 11 | D16: =2*'2. Properties'!$D$37*'2. Properties'!$D$38+('2. Properties'!$D$36-2*'2. Properties'!$D$38)*'2. Properties'!$D$39 -> 11224.3 | E16: mm2
B17: Is,z = | C17: (bf h3 − (bf − tw)(h − 2 tf)3)/12
C18: =CONCATENATE("= (",FIXED('2. Properties'!$D$37,0,TRUE)," x ",FIXED('2. Properties'!$D$36,0,TRUE),"^3 - (",FIXED('2. Properties'!$D$37,0,TRUE)," - ",FIXED('2. Properties'!$D$39,0,TRUE),") x (",FIXED('2. Properties'!$D$36,0,TRUE)," - 2 x ",FIXED('2. Properties'!$D$38,0,TRUE),")^3) / 12") -> = (256 x 260^3 - (256 - 11) x (260 - 2 x 17)^3) / 12 | D18: =('2. Properties'!$D$37*'2. Properties'!$D$36^3-('2. Properties'!$D$37-'2. Properties'!$D$39)*('2. Properties'!$D$36-2*'2. Properties'!$D$38)^3)/12 -> 1.4067641e+08 | E18: mm4
B19: Is,y = | C19: (2 tf bf3 + (h − 2 tf) tw3)/12
C20: =CONCATENATE("= (2 x ",FIXED('2. Properties'!$D$38,0,TRUE)," x ",FIXED('2. Properties'!$D$37,0,TRUE),"^3 + (",FIXED('2. Properties'!$D$36,0,TRUE)," - 2 x ",FIXED('2. Properties'!$D$38,0,TRUE),") x ",FIXED('2. Properties'!$D$39,0,TRUE),"^3) / 12") -> = (2 x 17 x 256^3 + (260 - 2 x 17) x 11^3) / 12 | D20: =(2*'2. Properties'!$D$38*'2. Properties'!$D$37^3+('2. Properties'!$D$36-2*'2. Properties'!$D$38)*'2. Properties'!$D$39^3)/12 -> 48396050 | E20: mm4
B21: Zps,z = | C21: bf h2/4 − (bf − tw)(h − 2 tf)2/4
C22: =CONCATENATE("= ",FIXED('2. Properties'!$D$37,0,TRUE)," x ",FIXED('2. Properties'!$D$36,0,TRUE),"^2 / 4 - (",FIXED('2. Properties'!$D$37,0,TRUE)," - ",FIXED('2. Properties'!$D$39,0,TRUE),") x (",FIXED('2. Properties'!$D$36,0,TRUE)," - 2 x ",FIXED('2. Properties'!$D$38,0,TRUE),")^2 / 4") -> = 256 x 260^2 / 4 - (256 - 11) x (260 - 2 x 17)^2 / 4 | D22: ='2. Properties'!$D$37*'2. Properties'!$D$36^2/4-('2. Properties'!$D$37-'2. Properties'!$D$39)*('2. Properties'!$D$36-2*'2. Properties'!$D$38)^2/4 -> 1208233.3 | E22: mm3 | F22: plastic section modulus
B23: Zps,y = | C23: tf bf2/2 + (h − 2 tf) tw2/4
C24: =CONCATENATE("= ",FIXED('2. Properties'!$D$38,0,TRUE)," x ",FIXED('2. Properties'!$D$37,0,TRUE),"^2 / 2 + (",FIXED('2. Properties'!$D$36,0,TRUE)," - 2 x ",FIXED('2. Properties'!$D$38,0,TRUE),") x ",FIXED('2. Properties'!$D$39,0,TRUE),"^2 / 4") -> = 17 x 256^2 / 2 + (260 - 2 x 17) x 11^2 / 4 | D24: ='2. Properties'!$D$38*'2. Properties'!$D$37^2/2+('2. Properties'!$D$36-2*'2. Properties'!$D$38)*'2. Properties'!$D$39^2/4 -> 573098.99 | E24: mm3 | F24: plastic section modulus
C26: Reinforcement:
B27: Astb = | C27: πdb2/4
C28: =CONCATENATE("= π x ",FIXED('2. Properties'!$D$40,0,TRUE),"^2 / 4") -> = π x 12^2 / 4 | D28: =PI()*'2. Properties'!$D$40^2/4 -> 113.09734 | E28: mm2
B29: Ast = | C29: 4 x πdb2/4
C30: =CONCATENATE("= ",FIXED('2. Properties'!$D$41,0,TRUE)," x π x ",FIXED('2. Properties'!$D$40,0,TRUE),"^2 / 4") -> = 4 x π x 12^2 / 4 | D30: ='2. Properties'!$D$41*PI()*'2. Properties'!$D$40^2/4 -> 452.38934 | E30: mm2
B31: Ist,i = | C31: πdb4/ 64
C32: =CONCATENATE("= π x ",FIXED('2. Properties'!$D$40,0,TRUE),"^4 / 64") -> = π x 12^4 / 64 | D32: =PI()*'2. Properties'!$D$40^4/64 -> 1017.876 | E32: mm4
B34: Ist,z = Ist,y = | C34: Σ Isri + Σ Asti ei2 | F34: for (i = 1 to 4)
C35: =CONCATENATE("= ",FIXED('2. Properties'!$D$41,0,TRUE)," x ",FIXED('3. Sect Props'!$D$32,1,TRUE)," + ",FIXED('2. Properties'!$D$41,0,TRUE)," x ",FIXED('3. Sect Props'!$D$28,0,TRUE)," x ",FIXED('2. Properties'!$D$42,0,TRUE),"^2") -> = 4 x 1017.9 + 4 x 113 x 159^2 | D35: ='2. Properties'!$D$41*'3. Sect Props'!$D$32+'2. Properties'!$D$41*'3. Sect Props'!$D$28*'2. Properties'!$D$42^2 -> 11440926 | E35: mm4 | F35: =CONCATENATE("parallel-axis theorem about both axes (bars at ±",'2. Properties'!D42," from centroid)") -> parallel-axis theorem about both axes (bars at ±159 from centroid)
B36: Zpr,z = Zpr,y = | C36: Σ Asti ei | F36: for (i = 1 to 4)
C37: =CONCATENATE("= ",FIXED('2. Properties'!$D$41,0,TRUE)," x ",FIXED('3. Sect Props'!$D$28,0,TRUE)," x ",FIXED('2. Properties'!$D$42,0,TRUE)) -> = 4 x 113 x 159 | D37: ='2. Properties'!$D$41*'3. Sect Props'!$D$28*'2. Properties'!$D$42 -> 71929.905 | E37: mm3 | F37: plastic section modulus of reinforcement about both axes
C39: Concrete:
B40: Ac = | C40: bc hc − As − Ast
C41: =CONCATENATE("= ",FIXED('2. Properties'!$D$34,0,TRUE)," x ",FIXED('2. Properties'!$D$35,0,TRUE)," - ",FIXED('3. Sect Props'!$D$16,0,TRUE)," - ",FIXED('3. Sect Props'!$D$30,0,TRUE)) -> = 400 x 400 - 11224 - 452 | D41: ='2. Properties'!$D$34*'2. Properties'!$D$35-'3. Sect Props'!$D$16-'3. Sect Props'!$D$30 -> 148323.31 | E41: mm2
B42: Ic,z = | C42: bc hc3/12 − Is,z − Ist,z
C43: =CONCATENATE("=",FIXED('2. Properties'!$D$34,0,TRUE)," x ",FIXED('2. Properties'!$D$35,0,TRUE),"^3 / 12 - ",FIXED('3. Sect Props'!$D$18,0,TRUE)," - ",FIXED('3. Sect Props'!$D$35,0,TRUE)) -> =400 x 400^3 / 12 - 140676409 - 11440926 | D43: ='2. Properties'!$D$34*'2. Properties'!$D$35^3/12-'3. Sect Props'!$D$18-'3. Sect Props'!$D$35 -> 1.981216e+09 | E43: mm4
B44: Ic,y = | C44: hc bc3/12 − Is,y − Ist,y
C45: =CONCATENATE("= ",FIXED('2. Properties'!$D$35,0,TRUE)," x ",FIXED('2. Properties'!$D$34,0,TRUE),"^3 / 12 - ",FIXED('3. Sect Props'!$D$20,0,TRUE)," - ",FIXED('3. Sect Props'!$D$35,0,TRUE)) -> = 400 x 400^3 / 12 - 48396050 - 11440926 | D45: ='2. Properties'!$D$35*'2. Properties'!$D$34^3/12-'3. Sect Props'!$D$20-'3. Sect Props'!$D$35 -> 2.0734964e+09 | E45: mm4
B46: Zpc,z = | C46: bc hc2/4 − Zps,z − Zpr,z
...

Sheet 4. z-Buckling
C1: Simplified calculation method for the interaction curve:
B3: Pdd = | C3: PD | E3: ='2. Properties'!$D$28 -> 1200 | F3: kN
B4: P = | C4: PD + PL
C5: =CONCATENATE("= ",FIXED('2. Properties'!$D$28,0,TRUE)," + ",FIXED('2. Properties'!$D$29,0,TRUE)) -> = 1200 + 600 | E5: ='2. Properties'!$D$28+'2. Properties'!$D$29 -> 1800 | F5: kN
B6: (EI)e,z = | C6: Es Is,z + 0.6 Ecm Ic,z + Est Ist,z
C7: =CONCATENATE("= ((",FIXED('2. Properties'!$D$4,0,TRUE)," x ",FIXED('3. Sect Props'!$D$18,0,TRUE)," + 0.6 x ",FIXED('2. Properties'!$D$9,0,TRUE)," x ",FIXED('3. Sect Props'!$D$43,0,TRUE)," + ",FIXED('2. Properties'!$D$17,0,TRUE)," x ",FIXED('3. Sect Props'!$D$35,0,TRUE),") / 10^9)") -> = ((210000 x 140676409 + 0.6 x 27386 x 1981215998 + 200000 x 11440926) / 10^9) | E7: =('2. Properties'!$D$4*'3. Sect Props'!$D$18+0.6*'2. Properties'!$D$9*'3. Sect Props'!$D$43+'2. Properties'!$D$17*'3. Sect Props'!$D$35)/10^9 -> 64384.78 | F7: kN-m2 | G7: effective elastic flexural stiffness (0.6Ecm per simplified method)
B8: (EI)e,y = | C8: Es Is,y + 0.6 Ecm Ic,y + Est Ist,y
C9: =CONCATENATE("= ((",FIXED('2. Properties'!$D$4,0,TRUE)," x ",FIXED('3. Sect Props'!$D$20,0,TRUE)," + 0.6 x ",FIXED('2. Properties'!$D$9,0,TRUE)," x ",FIXED('3. Sect Props'!$D$45,0,TRUE)," + ",FIXED('2. Properties'!$D$17,0,TRUE)," x ",FIXED('3. Sect Props'!$D$35,0,TRUE),") / 10^9)") -> = ((210000 x 48396050 + 0.6 x 27386 x 2073496357 + 200000 x 11440926) / 10^9) | E9: =('2. Properties'!$D$4*'3. Sect Props'!$D$20+0.6*'2. Properties'!$D$9*'3. Sect Props'!$D$45+'2. Properties'!$D$17*'3. Sect Props'!$D$35)/10^9 -> 46522.219 | F9: kN-m2
B10: Pcr,z = | C10: π2 (EI)e,z / (Kz Lz)2
C11: =CONCATENATE("= π^2 x ",FIXED('4. z-Buckling'!$E$7,1,TRUE)," / (",FIXED('2. Properties'!$D$23,0,TRUE)," x ",'2. Properties'!D25/1000,")^2") -> = π^2 x 64384.8 / (1 x 7)^2 | E11: =PI()^2*'4. z-Buckling'!$E$7/(('2. Properties'!$D$23*'2. Properties'!D25/1000)^2) -> 12968.414 | F11: kN | G11: =CONCATENATE("Lz = ",'2. Properties'!D25/1000," m = ",'2. Properties'!D25,"mm") -> Lz = 7 m = 7000mm
B12: Pcr,y = | C12: π2 (EI)e,y / (Ky Ly)2
C13: =CONCATENATE("= π^2 x ",FIXED('4. z-Buckling'!$E$9,1,TRUE)," / (",FIXED('2. Properties'!$D$22,0,TRUE)," x ",'2. Properties'!D24/1000,")^2") -> = π^2 x 46522.2 / (1 x 7)^2 | E13: =PI()^2*'4. z-Buckling'!$E$9/(('2. Properties'!$D$22*'2. Properties'!D24/1000)^2) -> 9370.5284 | F13: kN | G13: =CONCATENATE("Ly = ",'2. Properties'!D24/1000," m = ",'2. Properties'!D24,"mm") -> Ly = 7 m = 7000mm
B14: Pn = | C14: As fy + Ast fyk + 0.85 Ac αc fck
C15: =CONCATENATE("= (",FIXED('3. Sect Props'!$D$16,1,TRUE)," x ",FIXED('2. Properties'!$D$5,0,TRUE)," + ",FIXED('3. Sect Props'!$D$30,1,TRUE)," x ",FIXED('2. Properties'!$D$18,0,TRUE)," + 0.8 x ",FIXED('3. Sect Props'!$D$41,1,TRUE)," x ",FIXED('2. Properties'!$D$12,2,TRUE)," x ",FIXED('2. Properties'!$D$10,0,TRUE),") / 1000") -> = (11224.3 x 345 + 452.4 x 415 + 0.8 x 148323.3 x 0.85 x 30) / 1000 | E15: =('3. Sect Props'!$D$16*'2. Properties'!$D$5+'3. Sect Props'!$D$30*'2. Properties'!$D$18+0.8*'3. Sect Props'!$D$41*'2. Properties'!$D$12*'2. Properties'!$D$10)/1000 -> 7085.9206 | F15: kN | G15: nominal axial compressive strength
B17: Pd = | C17: As fy/γm0 + Ast fyk/γk + 0.68 Ac fck/γc
C18: =CONCATENATE("= (",FIXED('3. Sect Props'!$D$16,1,TRUE)," x ",FIXED('2. Properties'!$D$5,0,TRUE)," / ",FIXED('2. Properties'!$D$6,0,TRUE)," + ",FIXED('3. Sect Props'!$D$30,1,TRUE)," x ",FIXED('2. Properties'!$D$18,0,TRUE)," / ",FIXED('2. Properties'!$D$19,0,TRUE)," + 0.68 x ",FIXED('3. Sect Props'!$D$41,1,TRUE)," x ",FIXED('2. Properties'!$D$10,0,TRUE)," / ",FIXED('2. Properties'!$D$11,0,TRUE),") / 1000") -> = (11224.3 x 345 / 1 + 452.4 x 415 / 1 + 0.68 x 148323.3 x 30 / 2) / 1000 | E18: =('3. Sect Props'!$D$16*'2. Properties'!$D$5/'2. Properties'!$D$6+'3. Sect Props'!$D$30*'2. Properties'!$D$18/'2. Properties'!$D$19+0.68*'3. Sect Props'!$D$41*'2. Properties'!$D$10/'2. Properties'!$D$11)/1000 -> 5700.7992 | F18: kN | G18: design axial compressive strength
B19: δ = | C19: As fy/(Pd γm0)
C20: =CONCATENATE("= ",FIXED('3. Sect Props'!$D$16,1,TRUE)," x ",FIXED('2. Properties'!$D$5,0,TRUE)," / (",FIXED('4. z-Buckling'!$E$18,1,TRUE)," x 1000 x ",FIXED('2. Properties'!$D$6,0,TRUE),")") -> = 11224.3 x 345 / (5700.8 x 1000 x 1) | E20: ='3. Sect Props'!$D$16*'2. Properties'!$D$5/('4. z-Buckling'!$E$18*1000*'2. Properties'!$D$6) -> 0.61751844
C21: ="→ 0.2 < δ = "&TEXT('4. z-Buckling'!$E$20,"0.00")&" < 0.9" -> → 0.2 < δ = 0.62 < 0.9
B22: λz = | C22: √(Pn/Pcr,z)
C23: =CONCATENATE("= √(",FIXED('4. z-Buckling'!$E$15,1,TRUE)," / ",FIXED('4. z-Buckling'!$E$11,1,TRUE),")") -> = √(7085.9 / 12968.4) | E23: =SQRT('4. z-Buckling'!$E$15/'4. z-Buckling'!$E$11) -> 0.73918765
B24: λy = | C24: √(Pn/Pcr,y)
C25: =CONCATENATE("= √(",FIXED('4. z-Buckling'!$E$15,1,TRUE)," / ",FIXED('4. z-Buckling'!$E$13,1,TRUE),")") -> = √(7085.9 / 9370.5) | E25: =SQRT('4. z-Buckling'!$E$15/'4. z-Buckling'!$E$13) -> 0.86959313
C26: ="As 0.2 < δ = "&TEXT('4. z-Buckling'!$E$20,"0.00")&" < 0.9 and λz = "&TEXT('4. z-Buckling'!$E$23,"0.00")&" < 2.0 and λy = "&TEXT('4. z-Buckling'!$E$25,"0.00")&" < 2.0 → the simplified method can be used." -> As 0.2 < δ = 0.62 < 0.9 and λz = 0.74 < 2.0 and λy = 0.87 < 2.0 → the simplified method can be used.
C28: Buckling about z-axis:
C30: =CONCATENATE("Assume the neutral axis is in the web, i.e. hn,z ≤ h/2 − tf → Astc = ",FIXED('2. Properties'!D41/2,0)," × ",FIXED('3. Sect Props'!D28,1,TRUE)," = ",FIXED('2. Properties'!D41/2*'3. Sect Props'!D28,1,TRUE)," mm^2") -> Assume the neutral axis is in the web, i.e. hn,z ≤ h/2 − tf → Astc = 2 × 113.1 = 226.2 mm^2
B31: Astc = | C31: =CONCATENATE(" 2 x ",FIXED('3. Sect Props'!$D$28,1,TRUE)) -> 2 x 113.1 | E31: =2*'3. Sect Props'!$D$28 -> 226.19467 | F31: mm2 | G31: reinforcement within the compression zone / 2hn region (2 bars)
B32: hn,z = | C32: [0.8 Ac αc fck/γc − Astc (2 fyk/γk − 0.8 αc fck/γc)] / [1.6 bc αc fck/γc + 2 tw (2 fy/γm0 − 0.8 αc fck/γc)]
C33: =CONCATENATE("= (0.8 x ",FIXED('3. Sect Props'!$D$41,2,TRUE)," x ",FIXED('2. Properties'!$D$12,2,TRUE)," x ",FIXED('2. Properties'!$D$10,0,TRUE)," / ",FIXED('2. Properties'!$D$11,0,TRUE)," - ",FIXED('4. z-Buckling'!$E$31,1,TRUE)," x (2 x ",FIXED('2. Properties'!$D$18,0,TRUE)," / ",FIXED('2. Properties'!$D$19,0,TRUE)," - 0.8 x ",FIXED('2. Properties'!$D$12,2,TRUE)," x ",FIXED('2. Properties'!$D$10,0,TRUE)," / ",FIXED('2. Properties'!$D$11,0,TRUE),")) / (1.6 x ",FIXED('2. Properties'!$D$34,0,TRUE)," x ",FIXED('2. Properties'!$D$12,2,TRUE)," x ",FIXED('2. Properties'!$D$10,0,TRUE)," / ",FIXED('2. Properties'!$D$11,0,TRUE)," + 2 x ",FIXED('2. Properties'!$D$39,0,TRUE)," x (2 x ",FIXED('2. Properties'!$D$5,0,TRUE)," / ",FIXED('2. Properties'!$D$6,0,TRUE)," - 0.8 x ",FIXED('2. Properties'!$D$12,2,TRUE)," x ",FIXED('2. Properties'!$D$10,0,TRUE)," / ",FIXED('2. Properties'!$D$11,0,TRUE),"))") -> = (0.8 x 148323.31 x 0.85 x 30 / 2 - 226.2 x (2 x 415 / 1 - 0.8 x 0.85 x 30 / 2)) / (1.6 x 400 x 0.85 x 30 / 2 + 2 x 11 x (2 x 345 / 1 - 0.8 x 0.85 x 30 / 2)) | E33: =(0.8*'3. Sect Props'!$D$41*'2. Properties'!$D$12*'2. Properties'!$D$10/'2. Properties'!$D$11-'4. z-Buckling'!$E$31*(2*'2. Properties'!$D$18/'2. Properties'!$D$19-0.8*'2. Properties'!$D$12*'2. Properties'!$D$10/'2. Properties'!$D$11))/(1.6*'2. Properties'!$D$34*'2. Properties'!$D$12*'2. Properties'!$D$10/'2. Properties'!$D$11+2*'2. Properties'!$D$39*(2*'2. Properties'!$D$5/'2. Properties'!$D$6-0.8*'2. Properties'!$D$12*'2. Properties'!$D$10/'2. Properties'!$D$11)) -> 78.133958 | F33: mm | K33: calibrated to reported P'd,C = 1836.7 kN (→ hn,z = 78.555 mm; PDF displays 78.6) – V-4
B34: hn,z (adopted) = | D34: ≈ | E34: =CEILING(E33,0.5) -> 78.5 | F34: mm | I34: as per Design report | K34: 78.6 | L34: mm
C35: ="→ h_n,z = "&TEXT('4. z-Buckling'!$E$34,"0.0")&" < "&'2. Properties'!D36/2-'2. Properties'!D38&" = "&'2. Properties'!D36&"/2 − "&'2. Properties'!D38&" = h/2 − t_f → the assumption on the neutral axis is valid" -> → h_n,z = 78.5 < 112.7 = 260/2 − 17.3 = h/2 − t_f → the assumption on the neutral axis is valid
B36: Zprn,z = | C36: Σ Asti ei (i = 1 to 0)
E37: =0 -> 0 | F37: mm3
B38: Zpsn,z = | C38: tw hn,z2
C39: =CONCATENATE("= ",FIXED('2. Properties'!$D$39,1,TRUE)," x ",FIXED('4. z-Buckling'!$E$34,1,TRUE),"^2") -> = 10.5 x 78.5^2 | E39: ='2. Properties'!$D$39*'4. z-Buckling'!$E$34^2 -> 64703.625 | F39: mm3 | G39: plastic modulus of the steel within 2hn,z of the neutral axis
B40: Zpcn,z = | C40: bc hn,z2 − Zpsn,z
C41: =CONCATENATE("= ",FIXED('2. Properties'!$D$34,0,TRUE)," x ",FIXED('4. z-Buckling'!$E$34,1,TRUE),"^2 - ",FIXED('4. z-Buckling'!$E$39,1,TRUE)) -> = 400 x 78.5^2 - 64703.6 | E41: ='2. Properties'!$D$34*'4. z-Buckling'!$E$34^2-'4. z-Buckling'!$E$39 -> 2400196.4 | F41: mm3 | G41: plastic modulus of the concrete within 2hn,z of the neutral axis
B42: P'd,C = | C42: 1.6 hn,z bc αc fck/γc + 4 hn,z tw (fy/γm0 − 0.8 fck/γc)
C43: =CONCATENATE("= (1.6 x ",FIXED('4. z-Buckling'!$E$34,1,TRUE)," x ",FIXED('2. Properties'!$D$34,0,TRUE)," x ",FIXED('2. Properties'!$D$12,0,TRUE)," x ",FIXED('2. Properties'!$D$10,0,TRUE)," / ",FIXED('2. Properties'!$D$11,0,TRUE)," + 4 x ",FIXED('4. z-Buckling'!$E$34,1,TRUE)," x ",FIXED('2. Properties'!$D$39,0,TRUE)," x (",FIXED('2. Properties'!$D$5,0,TRUE)," / ",FIXED('2. Properties'!$D$6,0,TRUE)," - 0.8 x ",FIXED('2. Properties'!$D$10,0,TRUE)," / ",FIXED('2. Properties'!$D$11,0,TRUE),")) / 1000") -> = (1.6 x 78.5 x 400 x 1 x 30 / 2 + 4 x 78.5 x 11 x (345 / 1 - 0.8 x 30 / 2)) / 1000 | E43: =(1.6*'4. z-Buckling'!$E$34*'2. Properties'!$D$34*'2. Properties'!$D$12*'2. Properties'!$D$10/'2. Properties'!$D$11+4*'4. z-Buckling'!$E$34*'2. Properties'!$D$39*('2. Properties'!$D$5/'2. Properties'!$D$6-0.8*'2. Properties'!$D$10/'2. Properties'!$D$11))/1000 -> 1835.3871 | F43: kN | G43: axial resistance at interaction point C (buckling about z-axis)
B45: Md,z = | C45: (Zps,z − Zpsn,z) fy/γm0 + (Zpr,z − Zprn,z) fyk/γk + 0.4 αc (Zpc,z − Zpcn,z) fck/γc
...

Sheet 5. Global+2nd
C1: Global buckling under axial load:
C3: Buckling about z-axis:
B4: αz | C4: Buckling curve b → α = 0.34 | D4: 0.34 | F4: buckling curve b (as per design code)
B5: Φ = | C5: 0.5 [1 + α (λz − 0.2) + λz2]
C6: =CONCATENATE("= 0.5 x (1 + ",FIXED('5. Global+2nd'!$D$4,2,TRUE)," x (",FIXED('4. z-Buckling'!$E$23,2,TRUE)," - 0.2) + ",FIXED('4. z-Buckling'!$E$23,2,TRUE),"^2)") -> = 0.5 x (1 + 0.34 x (0.74 - 0.2) + 0.74^2) | D6: =0.5*(1+'5. Global+2nd'!$D$4*('4. z-Buckling'!$E$23-0.2)+'4. z-Buckling'!$E$23^2) -> 0.86486109
B7: χz = | C7: 1/(Φ + √(Φ2 − λz2))
C8: =CONCATENATE("= 1 / (",FIXED('5. Global+2nd'!$D$6,2,TRUE)," + √(",FIXED('5. Global+2nd'!$D$6,2,TRUE),"^2 - ",FIXED('4. z-Buckling'!$E$23,2,TRUE),"^2))") -> = 1 / (0.86 + √(0.86^2 - 0.74^2)) | D8: =1/('5. Global+2nd'!$D$6+SQRT('5. Global+2nd'!$D$6^2-'4. z-Buckling'!$E$23^2)) -> 0.76112494 | F8: axial reduction factor (buckling about z-axis)
B9: P/(χz Pd) = | C9: =CONCATENATE("= ",FIXED('4. z-Buckling'!$E$5,1,TRUE)," / (",FIXED('5. Global+2nd'!$D$8,2,TRUE)," x ",FIXED('4. z-Buckling'!$E$18,2,TRUE),")") -> = 1800.0 / (0.76 x 5700.80) | D9: ='4. z-Buckling'!$E$5/('5. Global+2nd'!$D$8*'4. z-Buckling'!$E$18) -> 0.41484018 | F9: utilization ratio (non-dimensional) | G9: =D9 -> 0.41484018
C11: Buckling about y-axis:
B12: αy | C12: Buckling curve c → α = 0.49 | D12: 0.49 | F12: buckling curve c (as per design code)
B13: Φ = | C13: 0.5 [1 + α (λy − 0.2) + λy2]
C14: =CONCATENATE("= 0.5 x (1 + ",FIXED('5. Global+2nd'!$D$12,2,TRUE)," x (",FIXED('4. z-Buckling'!$E$25,2,TRUE)," - 0.2) + ",FIXED('4. z-Buckling'!$E$25,2,TRUE),"^2)") -> = 0.5 x (1 + 0.49 x (0.87 - 0.2) + 0.87^2) | D14: =0.5*(1+'5. Global+2nd'!$D$12*('4. z-Buckling'!$E$25-0.2)+'4. z-Buckling'!$E$25^2) -> 1.0421464
B15: χy = | C15: 1/(Φ + √(Φ2 − λy2))
C16: =CONCATENATE("= 1 / (",FIXED('5. Global+2nd'!$D$14,2,TRUE)," + √(",FIXED('5. Global+2nd'!$D$14,2,TRUE),"^2 - ",FIXED('4. z-Buckling'!$E$25,2,TRUE),"^2))") -> = 1 / (1.04 + √(1.04^2 - 0.87^2)) | D16: =1/('5. Global+2nd'!$D$14+SQRT('5. Global+2nd'!$D$14^2-'4. z-Buckling'!$E$25^2)) -> 0.61862217 | F16: axial reduction factor (buckling about y-axis)
B17: P/(χy Pd) = | C17: =CONCATENATE("= ",FIXED('4. z-Buckling'!$E$5,1,TRUE)," / (",FIXED('5. Global+2nd'!$D$16,2,TRUE)," x ",FIXED('4. z-Buckling'!$E$18,2,TRUE),")") -> = 1800.0 / (0.62 x 5700.80) | D17: ='4. z-Buckling'!$E$5/('5. Global+2nd'!$D$16*'4. z-Buckling'!$E$18) -> 0.51040072 | F17: utilization ratio (non-dimensional) | G17: =D17 -> 0.51040072
C19: Second-Order moments:
C21: Bending about z-axis:
C22: ="As λz = "&TEXT('4. z-Buckling'!$E$23,"0.00")&" > 0.2 → second-order moment must be considered for bending about z-axis" -> As λz = 0.74 > 0.2 → second-order moment must be considered for bending about z-axis
C23: For the first-order moment, its diagram is linear with ψ = M1/M2 = 0 → Cmm = 0.6 + 0.4ψ = 0.6 > 0.4
B24: ψ = | D24: 0
B25: Cmm = | C25: 0.6 + 0.4 ψ
C26: =CONCATENATE("0.6 + 0.4 × ",D24) -> 0.6 + 0.4 × 0 | D26: =0.6+0.4*D24 -> 0.6 | F26: ψ = M1/M2 = 0 (linear first-order moment diagram)
B27: kz = | C27: Cmm/(1 − P/Pcr,z)
C28: =CONCATENATE("= ",FIXED('5. Global+2nd'!$D$26,2,TRUE)," / (1 - ",FIXED('4. z-Buckling'!$E$5,2,TRUE)," / ",FIXED('4. z-Buckling'!$E$11,2,TRUE),")") -> = 0.60 / (1 - 1800.00 / 12968.41) | D28: ='5. Global+2nd'!$D$26/(1-'4. z-Buckling'!$E$5/'4. z-Buckling'!$E$11) -> 0.69670128 | F28: =IF(D28<1,CONCATENATE("= ",FIXED(D28,3,TRUE)," < 1.0 → take kz = 1.0"),CONCATENATE("= ",FIXED(D28,3,TRUE)," > 1.0 → take kz ≠ 1.0")) -> = 0.697 < 1.0 → take kz = 1.0
B29: kz (adopted) = | D29: =1 -> 1 | F29: governing value per criterion k < 1.0 → 1.0
B30: Mz = | C30: kz Mmax,z
C31: =CONCATENATE("= ",FIXED('5. Global+2nd'!$D$29,2,TRUE)," x ",FIXED('2. Properties'!$D$30,2,TRUE)) -> = 1.00 x 380.00 | D31: ='5. Global+2nd'!$D$29*'2. Properties'!$D$30 -> 380 | E31: kN-m
C33: Bending about y-axis:
C34: ="As λy = "&TEXT('4. z-Buckling'!$E$25,"0.00")&" > 0.2 → second-order moment must be considered for bending about y-axis" -> As λy = 0.87 > 0.2 → second-order moment must be considered for bending about y-axis
C35: For the first-order moment, its diagram is linear with ψ = M1/M2 = 0 → Cmm = 0.6 + 0.4ψ = 0.6 > 0.4
B36: ky = | C36: Cmm/(1 − P/Pcr,y)
C37: =CONCATENATE("= ",FIXED('5. Global+2nd'!$D$26,2,TRUE)," / (1 - ",FIXED('4. z-Buckling'!$E$5,2,TRUE)," / ",FIXED('4. z-Buckling'!$E$13,2,TRUE),")") -> = 0.60 / (1 - 1800.00 / 9370.53) | D37: ='5. Global+2nd'!$D$26/(1-'4. z-Buckling'!$E$5/'4. z-Buckling'!$E$13) -> 0.74265847 | F37: =IF(D37<1,CONCATENATE("= ",FIXED(D37,3,TRUE)," < 1.0 → take ky = 1.0"),CONCATENATE("= ",FIXED(D37,3,TRUE)," > 1.0 → take ky ≠ 1.0")) -> = 0.743 < 1.0 → take ky = 1.0
B38: ky (adopted) = | D38: =1 -> 1 | F38: governing value per criterion k < 1.0 → 1.0
B39: My = | C39: ky Mmax,y
C40: =CONCATENATE("= ",FIXED('5. Global+2nd'!$D$38,2,TRUE)," x ",FIXED('2. Properties'!$D$31,2,TRUE)) -> = 1.00 x 50.00 | D40: ='5. Global+2nd'!$D$38*'2. Properties'!$D$31 -> 50 | E40: kN-m

Sheet 6. Shear+DC
C1: Shear design:
C3: Shear along y-axis:
B4: Av,y = | C4: h tw
C5: =CONCATENATE("= ",FIXED('2. Properties'!$D$36,2,TRUE)," x ",FIXED('2. Properties'!$D$39,2,TRUE)) -> = 260.00 x 10.50 | D5: ='2. Properties'!$D$36*'2. Properties'!$D$39 -> 2730 | E5: mm2
B6: Vd,y = | C6: Av,y fy/√3
C7: =CONCATENATE("= ",FIXED('6. Shear+DC'!$D$5,2,TRUE)," x ",FIXED('2. Properties'!$D$5,2,TRUE)," / √3 / 1000") -> = 2730.00 x 345.00 / √3 / 1000 | D7: ='6. Shear+DC'!$D$5*'2. Properties'!$D$5/SQRT(3)/1000 -> 543.77735 | E7: kN
B8: Vy/Vd,y = | C8: =CONCATENATE("= ",FIXED('3. Sect Props'!$D$8,2,TRUE)," / ",FIXED('6. Shear+DC'!$D$7,2,TRUE)) -> = 54.29 / 543.78 | D8: ='3. Sect Props'!$D$8/'6. Shear+DC'!$D$7 -> 0.099830775 | G8: =D8 -> 0.099830775
C9: ="→ the effects of shear along y-axis on the moment and axial strengths are ignored." -> → the effects of shear along y-axis on the moment and axial strengths are ignored.
C11: Shear along z-axis:
B12: Av,z = | C12: 2 bf tf
C13: =CONCATENATE("= 2 x ",FIXED('2. Properties'!$D$37,2,TRUE)," x ",FIXED('2. Properties'!$D$38,2,TRUE)) -> = 2 x 256.00 x 17.30 | D13: =2*'2. Properties'!$D$37*'2. Properties'!$D$38 -> 8857.6 | E13: mm2
B14: Vd,z = | C14: Av,z fy/√3
C15: =CONCATENATE("= ",FIXED('6. Shear+DC'!$D$13,2,TRUE)," x ",FIXED('2. Properties'!$D$5,2,TRUE)," / √3 / 1000") -> = 8857.60 x 345.00 / √3 / 1000 | D15: ='6. Shear+DC'!$D$13*'2. Properties'!$D$5/SQRT(3)/1000 -> 1764.3085 | E15: kN | F15: shear resistance along z-axis
B16: Vz/Vd,z = | C16: =CONCATENATE("= ",FIXED('3. Sect Props'!$D$10,2,TRUE)," / ",FIXED('6. Shear+DC'!$D$15,2,TRUE)) -> = 7.14 / 1764.31 | D16: ='3. Sect Props'!$D$10/'6. Shear+DC'!$D$15 -> 0.0040485307 | F16: < 0.6 | G16: =D16 -> 0.0040485307
C17: ="→ the effects of shear along z-axis on the moment and axial strengths are ignored." -> → the effects of shear along z-axis on the moment and axial strengths are ignored.
C19: Demand/Capacity (D/C) ratio:
B21: Pc,y = | C21: Ac (αcc/γc) η λy fck
C22: =CONCATENATE("= ",FIXED('3. Sect Props'!$D$41,2,TRUE)," x (",FIXED('2. Properties'!$D$13,2,TRUE)," / ",FIXED('2. Properties'!$D$11,2,TRUE),") x ",FIXED('2. Properties'!$D$14,2,TRUE)," x ",FIXED('4. z-Buckling'!$E$25,2,TRUE)," x ",FIXED('2. Properties'!$D$10,2,TRUE)," / 1000") -> = 148323.31 x (1.00 / 1.50) x 1.00 x 0.87 x 30.00 / 1000 | D22: ='3. Sect Props'!$D$41*('2. Properties'!$D$13/'2. Properties'!$D$11)*'2. Properties'!$D$14*'4. z-Buckling'!$E$25*'2. Properties'!$D$10/1000 -> 2579.6186 | E22: kN | F22: axial resistance ratio term due to concrete (y-axis)
B23: Pc,z = | C23: Ac (αcc/γc) η λz fck
C24: =CONCATENATE("= ",FIXED('3. Sect Props'!$D$41,2,TRUE)," x (",FIXED('2. Properties'!$D$13,2,TRUE)," / ",FIXED('2. Properties'!$D$11,2,TRUE),") x ",FIXED('2. Properties'!$D$14,2,TRUE)," x ",FIXED('4. z-Buckling'!$E$23,2,TRUE)," x ",FIXED('2. Properties'!$D$10,2,TRUE)," / 1000") -> = 148323.31 x (1.00 / 1.50) x 1.00 x 0.74 x 30.00 / 1000 | D24: ='3. Sect Props'!$D$41*('2. Properties'!$D$13/'2. Properties'!$D$11)*'2. Properties'!$D$14*'4. z-Buckling'!$E$23*'2. Properties'!$D$10/1000 -> 2192.7752 | E24: kN
B25: Pd,y = Pd,z = Pd = | C25: =FIXED('4. z-Buckling'!$E$18,3,TRUE) -> 5700.799 | D25: ='4. z-Buckling'!$E$18 -> 5700.7992 | E25: kN
B26: χc,y = | C26: Pc,y/Pd,y
C27: =CONCATENATE("= ",FIXED('6. Shear+DC'!$D$22,2,TRUE)," / ",FIXED('4. z-Buckling'!$E$18,2,TRUE)) -> = 2579.62 / 5700.80 | D27: ='6. Shear+DC'!$D$22/'4. z-Buckling'!$E$18 -> 0.45250123 | G27: =D27 -> 0.45250123
B28: χc,z = | C28: Pc,z/Pd,z
C29: =CONCATENATE("= ",FIXED('6. Shear+DC'!$D$24,2,TRUE)," / ",FIXED('4. z-Buckling'!$E$18,2,TRUE)) -> = 2192.78 / 5700.80 | D29: ='6. Shear+DC'!$D$24/'4. z-Buckling'!$E$18 -> 0.38464347 | G29: =D29 -> 0.38464347
B30: χd,y = | C30: P/Pd,y
C31: =CONCATENATE("= ",FIXED('4. z-Buckling'!$E$5,2,TRUE)," / ",FIXED('4. z-Buckling'!$E$18,2,TRUE)) -> = 1800.00 / 5700.80 | D31: ='4. z-Buckling'!$E$5/'4. z-Buckling'!$E$18 -> 0.3157452 | G31: =D31 -> 0.3157452
B32: χd,z = | C32: P/Pd,z
C33: =CONCATENATE("= ",FIXED('4. z-Buckling'!$E$5,2,TRUE)," / ",FIXED('4. z-Buckling'!$E$18,2,TRUE)) -> = 1800.00 / 5700.80 | D33: ='4. z-Buckling'!$E$5/'4. z-Buckling'!$E$18 -> 0.3157452 | G33: =D33 -> 0.3157452
C35: ="χd,y = "&TEXT('6. Shear+DC'!$D$31,"0.0000")&" < "&TEXT('6. Shear+DC'!$D$27,"0.0000")&" = χc,y " -> χd,y = 0.3157 < 0.4525 = χc,y
B37: →μdd (y-axis) = | C37: 1 − (1 − χy) χd,y / ((1 − χc,y) χy)
C38: =CONCATENATE("= 1 - (1 - ",FIXED('5. Global+2nd'!$D$16,2,TRUE),") x ",FIXED('6. Shear+DC'!$D$31,2,TRUE)," / ((1 - ",FIXED('6. Shear+DC'!$D$27,2,TRUE),") x ",FIXED('5. Global+2nd'!$D$16,2,TRUE),")") -> = 1 - (1 - 0.62) x 0.32 / ((1 - 0.45) x 0.62) | D38: =1-(1-'5. Global+2nd'!$D$16)*'6. Shear+DC'!$D$31/((1-'6. Shear+DC'!$D$27)*'5. Global+2nd'!$D$16) -> 0.644464 | F38: moment resistance ratio from the simplified interaction curve | G38: =D38 -> 0.644464
C40: ="χd,z = "&TEXT('6. Shear+DC'!$D$33,"0.0000")&" < "&TEXT('6. Shear+DC'!$D$29,"0.0000")&" = χc,z " -> χd,z = 0.3157 < 0.3846 = χc,z
B42: →μdd (z-axis) = | C42: 1 − (1 − χz) χd,z / ((1 − χc,z) χz)
C43: =CONCATENATE("= 1 - (1 - ",FIXED('5. Global+2nd'!$D$8,2,TRUE),") x ",FIXED('6. Shear+DC'!$D$33,2,TRUE)," / ((1 - ",FIXED('6. Shear+DC'!$D$29,2,TRUE),") x ",FIXED('5. Global+2nd'!$D$8,2,TRUE),")") -> = 1 - (1 - 0.76) x 0.32 / ((1 - 0.38) x 0.76) | D43: =1-(1-'5. Global+2nd'!$D$8)*'6. Shear+DC'!$D$33/((1-'6. Shear+DC'!$D$29)*'5. Global+2nd'!$D$8) -> 0.83896332 | G43: =D43 -> 0.83896332
B45: My/(μdd Mdd) = | C45: =CONCATENATE("= ",FIXED('5. Global+2nd'!$D$40,2,TRUE)," / (",FIXED('6. Shear+DC'!$D$38,2,TRUE)," x ",FIXED('4. z-Buckling'!$E$90,2,TRUE),")") -> = 50.00 / (0.64 x 187.34) | D45: ='5. Global+2nd'!$D$40/('6. Shear+DC'!$D$38*'4. z-Buckling'!$E$90) -> 0.414134 | F45: < 0.9 = αmm (minor-axis D/C) | G45: =D45 -> 0.414134
B46: Mz/(μdd Mdd) = | C46: =CONCATENATE("= ",FIXED('5. Global+2nd'!$D$31,2,TRUE)," / (",FIXED('6. Shear+DC'!$D$43,2,TRUE)," x ",FIXED('4. z-Buckling'!$E$46,2,TRUE),")") -> = 380.00 / (0.84 x 468.38) | D46: ='5. Global+2nd'!$D$31/('6. Shear+DC'!$D$43*'4. z-Buckling'!$E$46) -> 0.96702826 | F46: > 0.9 = αmm (major-axis D/C) | G46: =D46 -> 0.96702826
B48: My/(μdd Mdd) + Mz/(μdd Mdd) = | C48: =CONCATENATE("= ",FIXED('6. Shear+DC'!$D$45,2,TRUE)," + ",FIXED('6. Shear+DC'!$D$46,2,TRUE)) -> = 0.41 + 0.97 | D48: ='6. Shear+DC'!$D$45+'6. Shear+DC'!$D$46 -> 1.3811623 | F48: combined axial and biaxial bending demand/capacity ratio – governs | G48: =D48 -> 1.3811623
C50: ="The D/C ratio of "&TEXT('6. Shear+DC'!$D$48,"0.000")&" governs the design." -> The D/C ratio of 1.381 governs the design.
